Workbook
Name Draft_Grid: OFFSET('Auction Draft'!$B$3,0,0,'Pool Settings'!$C$6,'Pool Settings'!$C$7)
Name Participants_List: OFFSET('Pool Settings'!$B$17,0,0,'Pool Settings'!$C$6,1)
Name Participants_Number: OFFSET('Pool Settings'!$A$17,0,0,'Pool Settings'!$C$6,1)

Sheet Masters Field & Odds
A2: ⛳ 2026 MASTERS TOURNAMENT – FULL FIELD & OPENING ODDS
A3: Source: Easy Office Pools | Sorted: Best Odds → Longest Odds | As of April 7, 2026
F4: Masters Past Performance | K4: 2026 PGA Tour Recent Performance
A5: Golfer | B5: Tier | C5: Rank | D5: Odds | E5: Starting Bid | F5: 2025 | G5: 2024 | H5: 2023 | I5: 2022 | J5: 2021 | K5: Valero | L5: Houston | M5: Valspar | N5: Players | O5: Puerto Rico | P5: Arnold Palmer | Q5: Cognizant | R5: Genesis | S5: Pebble | T5: WM | U5: Farmers | V5: AmEx
A6: Scottie Scheffler | B6: 1 | C6: 1 | D6: 4/1 | E6: {=_xludf.IFS(B6=1,20,B6=2,10,B6=3,7.5,B6>=4,5)} -> #NAME? | F6: 4 | G6: 1 | H6: T10 | I6: 1 | J6: T18 | N6: T22 | P6: T24 | R6: T12 | S6: T4 | T6: T3 | V6: 1
A7: Jon Rahm | B7: 1 | C7: 30 | D7: 9/1 | E7: {=_xludf.IFS(B7=1,20,B7=2,15,B7=3,10,B7>=4,5)} -> #NAME? | F7: T14 | G7: T45 | H7: 1 | I7: T27 | J7: T5
A8: Rory McIlroy | B8: 1 | C8: 2 | D8: 10/1 | E8: {=_xludf.IFS(B8=1,20,B8=2,15,B8=3,10,B8>=4,5)} -> #NAME? | F8: 1 | G8: T22 | H8: CUT | I8: 2 | J8: CUT | N8: T46 | P8: WD | R8: T2 | S8: T14
A9: Bryson DeChambeau | B9: 1 | C9: 24 | D9: 11/1 | E9: {=_xludf.IFS(B9=1,20,B9=2,15,B9=3,10,B9>=4,5)} -> #NAME? | F9: T5 | G9: T6 | H9: CUT | I9: CUT | J9: T46
A10: Ludvig Aberg | B10: 2 | C10: 17 | D10: 18/1 | E10: {=_xludf.IFS(B10=1,20,B10=2,15,B10=3,10,B10>=4,5)} -> #NAME? | F10: 7 | G10: 2 | K10: T5 | N10: T5 | P10: T3 | R10: T20 | S10: T37 | U10: CUT | V10: WD
A11: Xander Schauffele | B11: 2 | C11: 10 | D11: 19/1 | E11: {=_xludf.IFS(B11=1,20,B11=2,15,B11=3,10,B11>=4,5)} -> #NAME? | F11: T8 | G11: 8 | H11: T10 | I11: CUT | J11: T3 | M11: T4 | N11: 3 | P11: T24 | R11: T7 | S11: T19 | T11: T41 | U11: CUT
A12: Cameron Young | B12: 2 | C12: 3 | D12: 24/1 | E12: {=_xludf.IFS(B12=1,20,B12=2,15,B12=3,10,B12>=4,5)} -> #NAME? | F12: CUT | G12: T9 | H12: T7 | I12: CUT | N12: 1 | P12: T3 | R12: T7 | S12: T55 | T12: T41 | U12: T22
A13: Tommy Fleetwood | B13: 2 | C13: 4 | D13: 25/1 | E13: {=_xludf.IFS(B13=1,20,B13=2,15,B13=3,10,B13>=4,5)} -> #NAME? | F13: T21 | G13: T3 | H13: 33 | I13: T14 | J13: T46 | K13: T10 | N13: T8 | P13: 49 | R13: T7 | S13: T4
A14: Matt Fitzpatrick | B14: 2 | C14: 6 | D14: 26/1 | E14: {=_xludf.IFS(B14=1,20,B14=2,15,B14=3,10,B14>=4,5)} -> #NAME? | F14: T40 | G14: T22 | H14: T10 | I14: T14 | J14: T34 | M14: 1 | N14: 2 | P14: T41 | R14: T24 | S14: T14 | T14: 9 | V14: T63
A15: Collin Morikawa | B15: 2 | C15: 7 | D15: 31/1 | E15: {=_xludf.IFS(B15=1,20,B15=2,15,B15=3,10,B15>=4,5)} -> #NAME? | F15: T14 | G15: T3 | H15: T10 | I15: 5 | J15: T18 | N15: WD | P15: 5 | R15: T7 | S15: 1 | T15: T54
A16: Justin Rose | B16: 2 | C16: 9 | D16: 36/1 | E16: {=_xludf.IFS(B16=1,20,B16=2,15,B16=3,10,B16>=4,5)} -> #NAME? | F16: 2 | G16: CUT | H16: T16 | I16: CUT | J16: 7 | N16: T13 | P16: CUT | R16: CUT | S16: T37 | U16: 1 | V16: CUT
A17: Jordan Spieth | B17: 2 | C17: 61 | D17: 38/1 | E17: {=_xludf.IFS(B17=1,20,B17=2,15,B17=3,10,B17>=4,5)} -> #NAME? | F17: T14 | G17: CUT | H17: T4 | I17: CUT | J17: T3 | K17: T63 | M17: T11 | N17: T32 | P17: T11 | R17: T12 | S17: T29 | T17: CUT
A18: Brooks Koepka | B18: 2 | C18: 169 | D18: 38/1 | E18: {=_xludf.IFS(B18=1,20,B18=2,15,B18=3,10,B18>=4,5)} -> #NAME? | F18: CUT | G18: T45 | H18: T2 | I18: CUT | J18: CUT | L18: CUT | M18: T18 | N18: T13 | Q18: T9 | T18: CUT | U18: T56
A19: Hideki Matsuyama | B19: 2 | C19: 14 | D19: 39/1 | E19: {=_xludf.IFS(B19=1,20,B19=2,15,B19=3,10,B19>=4,5)} -> #NAME? | F19: T21 | G19: T38 | H19: T16 | I19: T14 | J19: 1 | K19: T21 | N19: T27 | P19: T41 | R19: T28 | S19: T8 | T19: 2 | U19: T11
A20: Robert MacIntyre | B20: 3 | C20: 8 | D20: 40/1 | E20: {=_xludf.IFS(B20=1,20,B20=2,15,B20=3,10,B20>=4,5)} -> #NAME? | K20: T2 | N20: 4 | P20: T24 | R20: T20 | S20: T37 | V20: T38
A21: Russell Henley | B21: 3 | C21: 12 | D21: 42/1 | E21: {=_xludf.IFS(B21=1,20,B21=2,15,B21=3,10,B21>=4,5)} -> #NAME? | F21: CUT | G21: T38 | H21: T4 | I21: T30 | K21: CUT | N21: T13 | P21: T6 | R21: CUT | S21: T19 | V21: T8
A22: Chris Gotterup | B22: 3 | C22: 11 | D22: 43/1 | E22: {=_xludf.IFS(B22=1,20,B22=2,15,B22=3,10,B22>=4,5)} -> #NAME? | L22: T6 | N22: T56 | P22: T18 | R22: CUT | S22: T37 | T22: 1 | U22: T18
A23: Patrick Reed | B23: 3 | C23: 23 | D23: 45/1 | E23: {=_xludf.IFS(B23=1,20,B23=2,15,B23=3,10,B23>=4,5)} -> #NAME? | F23: 3 | G23: T12 | H23: T4 | I23: T35 | J23: T8
A24: Viktor Hovland | B24: 3 | C24: 22 | D24: 46/1 | E24: {=_xludf.IFS(B24=1,20,B24=2,15,B24=3,10,B24>=4,5)} -> #NAME? | F24: T21 | G24: CUT | H24: T7 | I24: T27 | J24: T21 | M24: CUT | N24: T13 | P24: T13 | R24: T41 | S24: T58 | T24: T10
A25: Si Woo Kim | B25: 3 | C25: 28 | D25: 47/1 | E25: {=_xludf.IFS(B25=1,20,B25=2,15,B25=3,10,B25>=4,5)} -> #NAME? | G25: T30 | H25: T29 | I25: T39 | J25: T12 | K25: T10 | N25: T50 | P25: T13 | R25: T34 | S25: T45 | T25: T3 | U25: T2 | V25: T6
A26: Min Woo Lee | B26: 3 | C26: 25 | D26: 54/1 | E26: {=_xludf.IFS(B26=1,20,B26=2,15,B26=3,10,B26>=4,5)} -> #NAME? | F26: 49 | G26: T22 | H26: CUT | I26: T14 | L26: T3 | N26: T32 | P26: T6 | R26: T12 | S26: T2 | T26: T28 | V26: T38
A27: Justin Thomas | B27: 3 | C27: 15 | D27: 55/1 | E27: {=_xludf.IFS(B27=1,20,B27=2,15,B27=3,10,B27>=4,5)} -> #NAME? | F27: T36 | G27: CUT | H27: CUT | I27: T8 | J27: T21 | M27: T30 | N27: T8 | P27: CUT
A28: Patrick Cantlay | B28: 3 | C28: 35 | D28: 57/1 | E28: {=_xludf.IFS(B28=1,20,B28=2,15,B28=3,10,B28>=4,5)} -> #NAME? | F28: T36 | G28: T22 | H28: T14 | I28: T39 | J28: CUT | M28: T7 | N28: T32 | P28: CUT | R28: T37 | S28: T14 | U28: CUT | V28: T13
A29: Adam Scott | B29: 3 | C29: 53 | D29: 62/1 | E29: {=_xludf.IFS(B29=1,20,B29=2,15,B29=3,10,B29>=4,5)} -> #NAME? | F29: CUT | G29: T22 | H29: T39 | I29: T48 | J29: 54 | L29: T21 | N29: T56 | P29: T11 | R29: 4 | U29: T30 | V29: T24
A30: Akshay Bhatia | B30: 3 | C30: 21 | D30: 66/1 | E30: {=_xludf.IFS(B30=1,20,B30=2,15,B30=3,10,B30>=4,5)} -> #NAME? | F30: T42 | G30: T35 | N30: T13 | P30: 1 | R30: T16 | S30: T6 | T30: T3 | U30: CUT | V30: CUT
A31: Sepp Straka | B31: 3 | C31: 13 | D31: 67/1 | E31: {=_xludf.IFS(B31=1,20,B31=2,15,B31=3,10,B31>=4,5)} -> #NAME? | F31: CUT | G31: T16 | H31: T46 | I31: T30 | K31: CUT | N31: T8 | P31: T13 | R31: T50 | S31: T2 | T31: T18 | V31: CUT
A32: Tyrrell Hatton | B32: 3 | C32: 31 | D32: 69/1 | E32: {=_xludf.IFS(B32=1,20,B32=2,15,B32=3,10,B32>=4,5)} -> #NAME? | F32: T14 | G32: T9 | H32: T34 | I32: 52 | J32: T18
A33: Jason Day | B33: 3 | C33: 41 | D33: 69/1 | E33: {=_xludf.IFS(B33=1,20,B33=2,15,B33=3,10,B33>=4,5)} -> #NAME? | F33: T8 | G33: T30 | H33: T39 | J33: CUT | L33: T6 | N33: T59 | P33: CUT | R33: CUT | S33: T24 | U33: T38 | V33: T2
A34: Jake Knapp | B34: 3 | C34: 42 | D34: 69/1 | E34: {=_xludf.IFS(B34=1,20,B34=2,15,B34=3,10,B34>=4,5)} -> #NAME? | G34: T55 | L34: T6 | N34: CUT | R34: 6 | S34: T8 | T34: 8 | U34: T5
A35: Shane Lowry | B35: 3 | C35: 32 | D35: 70/1 | E35: {=_xludf.IFS(B35=1,20,B35=2,15,B35=3,10,B35>=4,5)} -> #NAME? | F35: T42 | G35: T43 | H35: T16 | I35: T3 | J35: T21 | L35: T28 | N35: CUT | P35: CUT | Q35: T2 | R35: T24 | S35: T8
A36: Sam Burns | B36: 4 | C36: 33 | D36: 72/1 | E36: {=_xludf.IFS(B36=1,20,B36=2,15,B36=3,10,B36>=4,5)} -> #NAME? | F36: T46 | G36: CUT | H36: T29 | I36: CUT | L36: T21 | N36: T13 | P36: CUT | R36: CUT | S36: T6 | T36: CUT | V36: T27
A37: Corey Conners | B37: 4 | C37: 44 | D37: 82/1 | E37: {=_xludf.IFS(B37=1,20,B37=2,15,B37=3,10,B37>=4,5)} -> #NAME? | F37: T8 | G37: T38 | H37: CUT | I37: T6 | J37: T8 | M37: T14 | N37: T13 | P37: T33 | R37: T37 | S37: T70 | T37: CUT
A38: Nicolai Hojgaard | B38: 4 | C38: 36 | D38: 84/1 | E38: {=_xludf.IFS(B38=1,20,B38=2,15,B38=3,10,B38>=4,5)} -> #NAME? | F38: CUT | G38: T16 | L38: 2 | M38: T55 | N38: T27 | P38: T24 | Q38: T6 | T38: T3 | U38: T22
A39: J.J. Spaun | B39: 4 | C39: 5 | D39: 88/1 | E39: {=_xludf.IFS(B39=1,20,B39=2,15,B39=3,10,B39>=4,5)} -> #NAME? | F39: 50 | I39: T23 | K39: 1 | M39: CUT | N39: T24 | P39: CUT | R39: CUT | S39: T45 | U39: CUT
A40: Kurt Kitayama | B40: 4 | C40: 34 | D40: 88/1 | E40: {=_xludf.IFS(B40=1,20,B40=2,15,B40=3,10,B40>=4,5)} -> #NAME? | G40: T35 | H40: CUT | L40: T60 | N40: CUT | P40: T18 | R40: T2 | S40: T48 | T40: T24 | V40: CUT
A41: Jacob Bridgeman | B41: 4 | C41: 18 | D41: 94/1 | E41: {=_xludf.IFS(B41=1,20,B41=2,15,B41=3,10,B41>=4,5)} -> #NAME? | M41: T14 | N41: T5 | P41: T18 | R41: 1 | S41: T8 | T41: T18 | V41: T13
...

Sheet Pool Settings
A2: ⛳ MASTERS POOL – CONFIGURATION & SETTINGS
A5: POOL LOGISTICS
B6: Number of Participants | C6: 6
B7: Golfers Per Team | C7: 5
B8: 1st Place Payout (% of Pot) | C8: 0.8 | D8: =C8*'Auction Draft'!B3 -> 452
B9: 2nd Place Payout (% of Pot) | C9: 0.2 | D9: =C9*'Auction Draft'!B3 -> 113
B10: 3rd Place Payout (% of Pot) | C10: 0 | D10: =C10*'Auction Draft'!B3 -> 0
B11: Payout Sum Check | C11: =C8+C9+C10 -> 1
A14: PARTICIPANT NAMES
A15: # | B15: Participant Name
A16: =IF(ROW()-15<=$C$6,ROW()-15,"") -> 1 | B16: Tommy
A17: =IF(ROW()-15<=$C$6,ROW()-15,"") -> 2 | B17: Grant
A18: =IF(ROW()-15<=$C$6,ROW()-15,"") -> 3 | B18: Gavin
A19: =IF(ROW()-15<=$C$6,ROW()-15,"") -> 4 | B19: Caleb
A20: =IF(ROW()-15<=$C$6,ROW()-15,"") -> 5 | B20: Ben
A21: =IF(ROW()-15<=$C$6,ROW()-15,"") -> 6 | B21: Ethan
A22: =IF(ROW()-15<=$C$6,ROW()-15,"")
A23: =IF(ROW()-15<=$C$6,ROW()-15,"")
A24: =IF(ROW()-15<=$C$6,ROW()-15,"")
A25: =IF(ROW()-15<=$C$6,ROW()-15,"")
A26: =IF(ROW()-15<=$C$6,ROW()-15,"")
A27: =IF(ROW()-15<=$C$6,ROW()-15,"")
A28: =IF(ROW()-15<=$C$6,ROW()-15,"")
A29: =IF(ROW()-15<=$C$6,ROW()-15,"")
A30: =IF(ROW()-15<=$C$6,ROW()-15,"")

Sheet Auction Draft
A2: ⛳ MASTERS POOL – AUCTION DRAFT RESULTS
A3: TOTAL POT: | B3: =SUM(D5:D12)+SUM(F5:F12)+SUM(H5:H12)+SUM(J5:J12)+SUM(L5:L12) -> 565
A4: # | B4: Participant | C4: =IF(INT((COLUMN()-3)/2)+1<='Pool Settings'!$C$7, "Golfer " & (INT((COLUMN()-3)/2)+1), "") -> Golfer 1 | D4: Bid 1 ($) | E4: =IF(INT((COLUMN()-3)/2)+1<='Pool Settings'!$C$7, "Golfer " & (INT((COLUMN()-3)/2)+1), "") -> Golfer 2 | F4: Bid 2 ($) | G4: =IF(INT((COLUMN()-3)/2)+1<='Pool Settings'!$C$7, "Golfer " & (INT((COLUMN()-3)/2)+1), "") -> Golfer 3 | H4: Bid 3 ($) | I4: =IF(INT((COLUMN()-3)/2)+1<='Pool Settings'!$C$7, "Golfer " & (INT((COLUMN()-3)/2)+1), "") -> Golfer 4 | J4: Bid 4 ($) | K4: =IF(INT((COLUMN()-3)/2)+1<='Pool Settings'!$C$7, "Golfer " & (INT((COLUMN()-3)/2)+1), "") -> Golfer 5 | L4: Bid 5 ($) | M4: Total Bid ($)
A5: =IF(B5<>"",ROW()-4,"") -> 1 | B5: {=IF(ROW()-4<='Pool Settings'!$C$6, INDEX('Pool Settings'!$B$16:$B$100, ROW()-4), "")} -> Tommy | C5: Scottie Scheffler | D5: 35 | E5: Brooks Koepka | F5: 15 | G5: Viktor Hovland | H5: 15 | I5: Patrick Cantlay | J5: 10 | K5: Tyrell Hatton | L5: 10 | M5: =D5+F5+H5+J5+L5 -> 85
A6: =IF(B6<>"",ROW()-4,"") -> 2 | B6: {=IF(ROW()-4<='Pool Settings'!$C$6, INDEX('Pool Settings'!$B$16:$B$100, ROW()-4), "")} -> Grant | C6: John Rahm | D6: 25 | E6: Matt Fitzpatrick | F6: 20 | G6: Robert MacIntyre | H6: 15 | I6: Patrick Reed | J6: 25 | K6: Max Homa | L6: 5 | M6: =D6+F6+H6+J6+L6 -> 90
A7: =IF(B7<>"",ROW()-4,"") -> 3 | B7: {=IF(ROW()-4<='Pool Settings'!$C$6, INDEX('Pool Settings'!$B$16:$B$100, ROW()-4), "")} -> Gavin | C7: Russell Henley | D7: 15 | E7: Min Woo Lee | F7: 15 | G7: Justin Thomas | H7: 10 | I7: Adam Scott | J7: 10 | K7: Corey Conners | L7: 5 | M7: =D7+F7+H7+J7+L7 -> 55
A8: =IF(B8<>"",ROW()-4,"") -> 4 | B8: {=IF(ROW()-4<='Pool Settings'!$C$6, INDEX('Pool Settings'!$B$16:$B$100, ROW()-4), "")} -> Caleb | C8: Rory McIlroy | D8: 30 | E8: Xander Schaufelle | F8: 25 | G8: Jordan Spieth | H8: 15 | I8: Chris Gotterup | J8: 25 | K8: Jake Knapp | L8: 10 | M8: =D8+F8+H8+J8+L8 -> 105
A9: =IF(B9<>"",ROW()-4,"") -> 5 | B9: {=IF(ROW()-4<='Pool Settings'!$C$6, INDEX('Pool Settings'!$B$16:$B$100, ROW()-4), "")} -> Ben | C9: Ludvig Aberg | D9: 35 | E9: Cam Young | F9: 25 | G9: Tommy Fleetwood | H9: 20 | I9: Collin Morikawa | J9: 35 | K9: Justin Rose | L9: 25 | M9: =D9+F9+H9+J9+L9 -> 140
A10: =IF(B10<>"",ROW()-4,"") -> 6 | B10: {=IF(ROW()-4<='Pool Settings'!$C$6, INDEX('Pool Settings'!$B$16:$B$100, ROW()-4), "")} -> Ethan | C10: Bryson Dechambeu | D10: 40 | E10: Hideki Matsuyama | F10: 25 | G10: Akshay Bhatia | H10: 10 | I10: Shane Lowry | J10: 10 | K10: JJ Spaun | L10: 5 | M10: =D10+F10+H10+J10+L10 -> 90
A11: =IF(B11<>"",ROW()-5,"") | B11: {=IF(ROW()-4<='Pool Settings'!$C$6, INDEX('Pool Settings'!$B$16:$B$100, ROW()-4), "")} | C11: =IF(OR($B11="", MOD(COLUMN()-3,2)=1, INT((COLUMN()-3)/2)+1>'Pool Settings'!$C$7), "", "") | D11: 0 | E11: =IF(OR($B11="", MOD(COLUMN()-3,2)=1, INT((COLUMN()-3)/2)+1>'Pool Settings'!$C$7), "", "") | F11: 0 | G11: =IF(OR($B11="", MOD(COLUMN()-3,2)=1, INT((COLUMN()-3)/2)+1>'Pool Settings'!$C$7), "", "") | H11: 0 | I11: =IF(OR($B11="", MOD(COLUMN()-3,2)=1, INT((COLUMN()-3)/2)+1>'Pool Settings'!$C$7), "", "") | J11: 0 | K11: =IF(OR($B11="", MOD(COLUMN()-3,2)=1, INT((COLUMN()-3)/2)+1>'Pool Settings'!$C$7), "", "") | L11: 0 | M11: =D11+F11+H11+J11+L11 -> 0
A12: =IF(B12<>"",ROW()-5,"") | B12: {=IF(ROW()-4<='Pool Settings'!$C$6, INDEX('Pool Settings'!$B$16:$B$100, ROW()-4), "")} | C12: =IF(OR($B12="", MOD(COLUMN()-3,2)=1, INT((COLUMN()-3)/2)+1>'Pool Settings'!$C$7), "", "") | D12: 0 | E12: =IF(OR($B12="", MOD(COLUMN()-3,2)=1, INT((COLUMN()-3)/2)+1>'Pool Settings'!$C$7), "", "") | F12: 0 | G12: =IF(OR($B12="", MOD(COLUMN()-3,2)=1, INT((COLUMN()-3)/2)+1>'Pool Settings'!$C$7), "", "") | H12: 0 | I12: =IF(OR($B12="", MOD(COLUMN()-3,2)=1, INT((COLUMN()-3)/2)+1>'Pool Settings'!$C$7), "", "") | J12: 0 | K12: =IF(OR($B12="", MOD(COLUMN()-3,2)=1, INT((COLUMN()-3)/2)+1>'Pool Settings'!$C$7), "", "") | L12: 0 | M12: =D12+F12+H12+J12+L12 -> 0
A13: =IF(B13<>"",ROW()-5,"") | B13: {=IF(ROW()-4<='Pool Settings'!$C$6, INDEX('Pool Settings'!$B$16:$B$100, ROW()-4), "")} | C13: =IF(OR($B13="", MOD(COLUMN()-3,2)=1, INT((COLUMN()-3)/2)+1>'Pool Settings'!$C$7), "", "") | D13: 0 | E13: =IF(OR($B13="", MOD(COLUMN()-3,2)=1, INT((COLUMN()-3)/2)+1>'Pool Settings'!$C$7), "", "") | F13: 0 | G13: =IF(OR($B13="", MOD(COLUMN()-3,2)=1, INT((COLUMN()-3)/2)+1>'Pool Settings'!$C$7), "", "") | H13: 0 | I13: =IF(OR($B13="", MOD(COLUMN()-3,2)=1, INT((COLUMN()-3)/2)+1>'Pool Settings'!$C$7), "", "") | J13: 0 | K13: =IF(OR($B13="", MOD(COLUMN()-3,2)=1, INT((COLUMN()-3)/2)+1>'Pool Settings'!$C$7), "", "") | L13: 0 | M13: =D13+F13+H13+J13+L13 -> 0
A14: =IF(B14<>"",ROW()-5,"") | B14: {=IF(ROW()-4<='Pool Settings'!$C$6, INDEX('Pool Settings'!$B$16:$B$100, ROW()-4), "")} | C14: =IF(OR($B14="", MOD(COLUMN()-3,2)=1, INT((COLUMN()-3)/2)+1>'Pool Settings'!$C$7), "", "") | D14: 0 | E14: =IF(OR($B14="", MOD(COLUMN()-3,2)=1, INT((COLUMN()-3)/2)+1>'Pool Settings'!$C$7), "", "") | F14: 0 | G14: =IF(OR($B14="", MOD(COLUMN()-3,2)=1, INT((COLUMN()-3)/2)+1>'Pool Settings'!$C$7), "", "") | H14: 0 | I14: =IF(OR($B14="", MOD(COLUMN()-3,2)=1, INT((COLUMN()-3)/2)+1>'Pool Settings'!$C$7), "", "") | J14: 0 | K14: =IF(OR($B14="", MOD(COLUMN()-3,2)=1, INT((COLUMN()-3)/2)+1>'Pool Settings'!$C$7), "", "") | L14: 0 | M14: =D14+F14+H14+J14+L14 -> 0
A15: =IF(B15<>"",ROW()-5,"") | B15: {=IF(ROW()-4<='Pool Settings'!$C$6, INDEX('Pool Settings'!$B$16:$B$100, ROW()-4), "")} | C15: =IF(OR($B15="", MOD(COLUMN()-3,2)=1, INT((COLUMN()-3)/2)+1>'Pool Settings'!$C$7), "", "") | D15: 0 | E15: =IF(OR($B15="", MOD(COLUMN()-3,2)=1, INT((COLUMN()-3)/2)+1>'Pool Settings'!$C$7), "", "") | F15: 0 | G15: =IF(OR($B15="", MOD(COLUMN()-3,2)=1, INT((COLUMN()-3)/2)+1>'Pool Settings'!$C$7), "", "") | H15: 0 | I15: =IF(OR($B15="", MOD(COLUMN()-3,2)=1, INT((COLUMN()-3)/2)+1>'Pool Settings'!$C$7), "", "") | J15: 0 | K15: =IF(OR($B15="", MOD(COLUMN()-3,2)=1, INT((COLUMN()-3)/2)+1>'Pool Settings'!$C$7), "", "") | L15: 0 | M15: =D15+F15+H15+J15+L15 -> 0
A16: =IF(B16<>"",ROW()-5,"") | B16: {=IF(ROW()-4<='Pool Settings'!$C$6, INDEX('Pool Settings'!$B$16:$B$100, ROW()-4), "")} | C16: =IF(OR($B16="", MOD(COLUMN()-3,2)=1, INT((COLUMN()-3)/2)+1>'Pool Settings'!$C$7), "", "") | D16: 0 | E16: =IF(OR($B16="", MOD(COLUMN()-3,2)=1, INT((COLUMN()-3)/2)+1>'Pool Settings'!$C$7), "", "") | F16: 0 | G16: =IF(OR($B16="", MOD(COLUMN()-3,2)=1, INT((COLUMN()-3)/2)+1>'Pool Settings'!$C$7), "", "") | H16: 0 | I16: =IF(OR($B16="", MOD(COLUMN()-3,2)=1, INT((COLUMN()-3)/2)+1>'Pool Settings'!$C$7), "", "") | J16: 0 | K16: =IF(OR($B16="", MOD(COLUMN()-3,2)=1, INT((COLUMN()-3)/2)+1>'Pool Settings'!$C$7), "", "") | L16: 0 | M16: =D16+F16+H16+J16+L16 -> 0
A17: =IF(B17<>"",ROW()-5,"") | B17: {=IF(ROW()-4<='Pool Settings'!$C$6, INDEX('Pool Settings'!$B$16:$B$100, ROW()-4), "")} | C17: =IF(OR($B17="", MOD(COLUMN()-3,2)=1, INT((COLUMN()-3)/2)+1>'Pool Settings'!$C$7), "", "") | D17: 0 | E17: =IF(OR($B17="", MOD(COLUMN()-3,2)=1, INT((COLUMN()-3)/2)+1>'Pool Settings'!$C$7), "", "") | F17: 0 | G17: =IF(OR($B17="", MOD(COLUMN()-3,2)=1, INT((COLUMN()-3)/2)+1>'Pool Settings'!$C$7), "", "") | H17: 0 | I17: =IF(OR($B17="", MOD(COLUMN()-3,2)=1, INT((COLUMN()-3)/2)+1>'Pool Settings'!$C$7), "", "") | J17: 0 | K17: =IF(OR($B17="", MOD(COLUMN()-3,2)=1, INT((COLUMN()-3)/2)+1>'Pool Settings'!$C$7), "", "") | L17: 0 | M17: =D17+F17+H17+J17+L17 -> 0
A18: =IF(B18<>"",ROW()-5,"") | B18: {=IF(ROW()-4<='Pool Settings'!$C$6, INDEX('Pool Settings'!$B$16:$B$100, ROW()-4), "")} | C18: =IF(OR($B18="", MOD(COLUMN()-3,2)=1, INT((COLUMN()-3)/2)+1>'Pool Settings'!$C$7), "", "") | D18: 0 | E18: =IF(OR($B18="", MOD(COLUMN()-3,2)=1, INT((COLUMN()-3)/2)+1>'Pool Settings'!$C$7), "", "") | F18: 0 | G18: =IF(OR($B18="", MOD(COLUMN()-3,2)=1, INT((COLUMN()-3)/2)+1>'Pool Settings'!$C$7), "", "") | H18: 0 | I18: =IF(OR($B18="", MOD(COLUMN()-3,2)=1, INT((COLUMN()-3)/2)+1>'Pool Settings'!$C$7), "", "") | J18: 0 | K18: =IF(OR($B18="", MOD(COLUMN()-3,2)=1, INT((COLUMN()-3)/2)+1>'Pool Settings'!$C$7), "", "") | L18: 0 | M18: =D18+F18+H18+J18+L18 -> 0
A19: =IF(B19<>"",ROW()-5,"") | B19: {=IF(ROW()-4<='Pool Settings'!$C$6, INDEX('Pool Settings'!$B$16:$B$100, ROW()-4), "")} | C19: =IF(OR($B19="", MOD(COLUMN()-3,2)=1, INT((COLUMN()-3)/2)+1>'Pool Settings'!$C$7), "", "") | D19: 0 | E19: =IF(OR($B19="", MOD(COLUMN()-3,2)=1, INT((COLUMN()-3)/2)+1>'Pool Settings'!$C$7), "", "") | F19: 0 | G19: =IF(OR($B19="", MOD(COLUMN()-3,2)=1, INT((COLUMN()-3)/2)+1>'Pool Settings'!$C$7), "", "") | H19: 0 | I19: =IF(OR($B19="", MOD(COLUMN()-3,2)=1, INT((COLUMN()-3)/2)+1>'Pool Settings'!$C$7), "", "") | J19: 0 | K19: =IF(OR($B19="", MOD(COLUMN()-3,2)=1, INT((COLUMN()-3)/2)+1>'Pool Settings'!$C$7), "", "") | L19: 0 | M19: =D19+F19+H19+J19+L19 -> 0
